Workbook

Sheet Android build
A1: Project Name | B1: DrugTime
A2: Module Name | B2: Build ứng dụng Android (BUILD)
A3: Created By | B3: zannguyen
A4: Creation Date | B4: 46303
A5: Reviewed By
A6: Reviewed Date
K7: Equivalence Partitioning | Q7: Kết quả flutter build apk --debug
A8: Test Case ID | B8: Description | C8: Precondition | D8: Test Steps | E8: Test Data | F8: Expected Result | G8: Actual Result | H8: Status | I8: Comments(if any) | K8: Field | L8: Valid | M8: Num | N8: Invalid | O8: Num | Q8: Rule | R8: R1 | S8: R2 | T8: R3
A9: TC-BUILD-01 | B9: Build APK debug trên mã nguồn chưa sửa (main 1dc7d37) để xác nhận lỗi | C9: frontend ở commit 1dc7d37 (main), chưa bật desugaring, flutter_timezone 2.1.0; Android SDK và JDK 17 đã cài | D9: 1. cd frontend/mobile 2. flutter build apk --debug --dart-define=DRUGTIME_API_BASE_URL=http://10.0.2.2:8000 | E9: Desugaring: không bật; flutter_timezone: ^2.0.1 | F9: Build fail ở task :app:checkDebugAarMetadata với thông báo "Dependency ':flutter_local_notifications' requires core library desugaring to be enabled for :app." | G9: Fail ở :app:checkDebugAarMetadata, đúng thông báo trên, exit 1 | H9: Pass | I9: AC1 (trước khi sửa) · Decision Table (R1) · EP (3,4) · evidence/implement-P1-before.log | K9: Cấu hình core library desugaring trong android/app/build.gradle.kts | L9: Bật (isCoreLibraryDesugaringEnabled = true + desugar_jdk_libs) | M9: 1 | N9: Không bật | O9: 3 | Q9: Bật desugaring? | R9: No | S9: Yes | T9: Yes
A10: TC-BUILD-02 | B10: Build APK debug khi chỉ bật desugaring, chưa nâng flutter_timezone | C10: Như TC-BUILD-01, đã thêm isCoreLibraryDesugaringEnabled = true và coreLibraryDesugaring("com.android.tools:desugar_jdk_libs:2.1.4") | D10: 1. cd frontend/mobile 2. flutter build apk --debug --dart-define=DRUGTIME_API_BASE_URL=http://10.0.2.2:8000 | E10: Desugaring: bật; flutter_timezone: 2.1.0 | F10: Build fail ở :flutter_timezone:compileDebugKotlin với "Unresolved reference 'Registrar'" | G10: Fail ở :flutter_timezone:compileDebugKotlin, FlutterTimezonePlugin.kt:12:48 Unresolved reference 'Registrar', exit 1 | H10: Pass | I10: AC1 · Decision Table (R2) · EP (1,4) · evidence/implement-P2.log | K10: Phiên bản flutter_timezone | L10: ≥ 3.0 (dùng 5.1.1, embedding v2) | M10: 2 | N10: 2.x (dùng PluginRegistry.Registrar đã bị gỡ) | O10: 4 | Q10: flutter_timezone ≥ 3.0? | R10: No | S10: No | T10: Yes
A11: TC-BUILD-03 | B11: Build APK debug sau khi sửa (bật desugaring và nâng flutter_timezone) | C11: frontend nhánh fix/adhoc-20261007-android-desugaring: desugaring bật, flutter_timezone ^5.1.1 | D11: 1. cd frontend/mobile 2. flutter build apk --debug --dart-define=DRUGTIME_API_BASE_URL=http://10.0.2.2:8000 | E11: Desugaring: bật; flutter_timezone: 5.1.1 | F11: Build thành công, tạo build/app/outputs/flutter-apk/app-debug.apk, exit 0 | G11: √ Built build\app\outputs\flutter-apk\app-debug.apk, exit 0 | H11: Pass | I11: AC1 (hồi quy) · Decision Table (R3) · EP (1,2) · evidence/implement-P3.log | Q11: Action | R11: R1 | S11: R2 | T11: R3
A12: TC-BUILD-04 | B12: Phân tích tĩnh mã Dart sau khi sửa | C12: Như TC-BUILD-03 | D12: 1. cd frontend/mobile 2. flutter analyze --no-fatal-infos | E12: (không có) | F12: No issues found! | G12: No issues found! (ran in 8.1s) | H12: Pass | I12: AC2 · evidence/implement-final-frontend.log | Q12: Fail :app:checkDebugAarMetadata (requires core library desugaring) | R12: X
A13: TC-BUILD-05 | B13: Chạy toàn bộ unit/widget test của Mobile App sau khi sửa | C13: Như TC-BUILD-03 | D13: 1. cd frontend/mobile 2. flutter test | E13: (không có) | F13: All tests passed!, không có test fail hay skip | G13: +331: All tests passed! | H13: Pass | I13: AC2 · evidence/implement-final-frontend.log | Q13: Fail :flutter_timezone:compileDebugKotlin (Unresolved reference 'Registrar') | S13: X
A14: TC-BUILD-06 | B14: Kiểm phụ thuộc trong pubspec sau khi sửa và không đổi mã Dart | C14: Như TC-BUILD-03 | D14: 1. Mở frontend/mobile/pubspec.yaml, tìm flutter_local_notifications, timezone, flutter_timezone 2. Mở pubspec.lock, xem khối flutter_timezone 3. git -C frontend diff --stat -- mobile/lib | E14: (không có) | F14: pubspec.yaml còn flutter_local_notifications ^17.2.2 và timezone ^0.9.4, flutter_timezone ^5.1.1; pubspec.lock khóa flutter_timezone 5.1.1; không có thay đổi trong mobile/lib | G14: pubspec.yaml dòng 19–21 đúng như mong đợi; pubspec.lock version "5.1.1"; diff mobile/lib rỗng | H14: Pass | I14: AC3 · manual · evidence/testcase-TC-BUILD-06.log | Q14: Build thành công app-debug.apk | T14: X
A15: TC-BUILD-07 | B15: Cài APK đã sửa lên Android emulator và mở app | C15: Android emulator (emulator-5554) đã khởi động xong; APK từ TC-BUILD-03 | D15: 1. adb -s emulator-5554 install -r build/app/outputs/flutter-apk/app-debug.apk 2. adb -s emulator-5554 shell monkey -p vn.drugtime.drugtime_mobile -c android.intent.category.LAUNCHER 1 3. Chờ 15 giây, kiểm tiến trình app và logcat 4. Chụp màn hình | E15: Gói vn.drugtime.drugtime_mobile | F15: Cài Success; app chạy (có pid), logcat không có FATAL EXCEPTION; màn hình hiện "Đăng nhập" với tab "Số điện thoại" và nút "Gửi mã OTP" | G15: Performing Streamed Install – Success; pid 6852; không có FATAL EXCEPTION; màn hình Đăng nhập hiện đúng | H15: Pass | I15: AC4 · manual · evidence/implement-P5.log, evidence/implement-P5-login.png
A16: TC-BUILD-08 | B16: Chạy workflow Mobile CI có bước build APK trên pull request | C16: Nhánh fix/adhoc-20261007-android-desugaring của frontend đã push và mở PR vào main | D16: 1. Mở tab Actions của PR 2. Xem job build-and-test của workflow Mobile CI | E16: Workflow .github/workflows/mobile-ci.yml (bước setup-java 17 và "Build Android APK (debug)") | F16: Mọi bước xanh, gồm "Build Android APK (debug)" | G16: PR frontend #27, run 37658903070 trên e897a56: conclusion=success; mọi bước success, gồm "Build Android APK (debug)" (✓ Built build/app/outputs/flutter-apk/app-debug.apk), thời gian job 5m44s | H16: Pass | I16: AC5 · manual (GitHub Actions) · evidence/ci-pr27.log
A17: TC-BUILD-09 | B17: Cài phụ thuộc theo đúng lockfile bằng Flutter stable của team | C17: Máy có Flutter stable bản mới nhất (Dart ≥ 3.13); frontend nhánh fix | D17: 1. cd frontend/mobile 2. flutter pub get --enforce-lockfile | E17: pubspec.lock đã sửa tối thiểu (flutter_timezone 5.1.1, thêm equatable 3.0.0) | F17: Thành công, không báo lockfile cần cập nhật | H17: Pending | I17: Error Guessing · manual · máy implement dùng Flutter master cũ hơn (Dart 3.12) nên không kiểm được. Bằng chứng gián tiếp: CI PR #27 (Flutter stable 3.x) chạy flutter pub get báo "Got dependencies!", không đổi phụ thuộc nào (evidence/ci-pr27.log); chưa chạy đúng --enforce-lockfile
G20: Pass | H20: =COUNTIF(H9:H17,"Pass")
G21: Fail | H21: =COUNTIF(H9:H17,"Fail")
G22: Pending | H22: =COUNTIF(H9:H17,"Pending")
G23: Total | H23: =SUM(H20:H22)

Sheet Đăng nhập người dùng
A1: Project Name | B1: DrugTime
A2: Module Name | B2: Đăng nhập người dùng (LOGIN)
A3: Created By | B3: zannguyen
A4: Creation Date | B4: 46303
A5: Reviewed By
A6: Reviewed Date
K7: Equivalence Partitioning | Q7: Kết quả POST /auth/mobile/verify
A8: Test Case ID | B8: Description | C8: Precondition | D8: Test Steps | E8: Test Data | F8: Expected Result | G8: Actual Result | H8: Status | I8: Comments(if any) | K8: Field | L8: Valid | M8: Num | N8: Invalid | O8: Num | Q8: Rule | R8: R1 | S8: R2 | T8: R3 | U8: R4 | V8: R5 | W8: R6
A9: TC-LOGIN-01 | B9: Đăng nhập lại bằng email OTP với tài khoản đã có hồ sơ | C9: Tài khoản email đã đăng nhập OTP một lần và hoàn thiện hồ sơ | D9: 1. Lấy mã OTP mới cho email 2. POST /auth/mobile/verify {email, token} | E9: email: it-login-<ngẫu nhiên>@example.com; token: mã 6 số từ Supabase | F9: 200; user_id trùng lần đầu; profile_complete=true; session.session_type="mobile"; expires_in = 864000 ± 60; không có field supabase, không có refresh_token; bảng users có đúng 1 dòng cho email | G9: Đúng như mong đợi | H9: Pass | I9: AC1 · Decision Table (R6) · EP (4,6) · test_returning_email_user_same_id_profile_complete__AC1 | K9: phone | L9: Số nội địa 0xxxxxxxxx Số quốc tế +84xxxxxxxxx Có khoảng trắng, gạch, khoảng trắng hai đầu | M9: 1 2 3 | N9: 84… thiếu dấu + Có ngoặc hoặc chữ Chữ số Unicode (full-width, Ả Rập) Khoảng trắng không ngắt ở giữa Độ dài < 9 hoặc > 16 ký tự (kể cả +) Sai kiểu JSON (số, mảng, object, bool) | O9: 13 14 15 16 17 18 | Q9: Định danh hợp lệ? | R9: No | S9: Yes | T9: Yes | U9: Yes | V9: Yes | W9: Yes
A10: TC-LOGIN-02 | B10: Đăng nhập bằng số điện thoại dạng nội địa | C10: Số thử test_otp 84900000001 = 123456 trên Supabase local | D10: 1. POST /auth/mobile/verify {phone: "0900000001", token: "123456"} 2. Đọc users.phone_number của user_id trả về | E10: phone: 0900000001; token: 123456 | F10: 200; users.phone_number = "+84900000001" | G10: 200; phone_number = +84900000001 | H10: Pass | I10: AC2 · EP (1,6) · test_local_phone_format_logs_in_and_wrong_otp_401__AC2 | K10: email | L10: Email chữ thường Có chữ hoa hoặc khoảng trắng hai đầu | M10: 4 5 | N10: Sai định dạng (thiếu @, thiếu tên miền, nhiều @, có khoảng trắng) Rỗng hoặc chỉ khoảng trắng (không có phone) | O10: 19 20 | Q10: Mã OTP đúng? | R10: - | S10: No | T10: Yes | U10: Yes | V10: Yes | W10: Yes
A11: TC-LOGIN-03 | B11: Xác thực số điện thoại với mã OTP sai | C11: Như TC-LOGIN-02 | D11: 1. POST /auth/mobile/verify {phone: "0900000001", token: "000000"} | E11: token: 000000 | F11: 401 {"detail":"Invalid credentials"}; không chứa msg, error_code, otp_expired của Supabase | G11: 401 {"detail":"Invalid credentials"} | H11: Pass | I11: AC2 · Decision Table (R2) · EP (21) · test_local_phone_format_logs_in_and_wrong_otp_401__AC2 | K11: token (OTP) | L11: Đúng mã 6 chữ số | M11: 6 | N11: Sai mã 6 chữ số Rỗng Chỉ khoảng trắng Sai độ dài, có chữ, rất dài Chuỗi injection/ký tự đặc biệt | O11: 21 22 23 24 25 | Q11: Tài khoản | R11: - | S11: - | T11: Đã xóa | U11: Admin | V11: Thường, chưa có hồ sơ | W11: Thường, đủ hồ sơ
A12: TC-LOGIN-04 | B12: Đăng nhập Mobile App bằng tài khoản admin | C12: Tài khoản có users.system_role = 'admin' | D12: 1. Lấy mã OTP email của admin 2. POST /auth/mobile/verify {email, token} | E12: email: it-login-admin-<ngẫu nhiên>@example.com | F12: 403 {"detail":"admin_must_use_web"}; không cấp session | G12: 403 {"detail":"admin_must_use_web"}, không có session | H12: Pass | I12: AC3 · Decision Table (R4) · test_admin_account_on_mobile_forbidden__AC3 | K12: ho_ten | L12: Tiếng Việt có dấu Emoji Chuỗi SQL/HTML/template (lưu như dữ liệu) Dài đúng 255 ký tự | M12: 7 8 9 10 | N12: Rỗng hoặc chỉ khoảng trắng Dài > 255 ký tự Có ký tự NUL | O12: 26 27 28 | Q12: Action | R12: R1 | S12: R2 | T12: R3 | U12: R4 | V12: R5 | W12: R6
A13: TC-LOGIN-05 | B13: Dùng phiên cũ và đăng nhập lại sau khi tài khoản bị xóa | C13: User đã đăng nhập, đang giữ phiên mobile hợp lệ | D13: 1. Đặt users.erased_at = now() (xóa trường định danh như SqlUsers.erase) 2. POST /auth/profile với phiên cũ 3. POST /auth/mobile/verify với mã OTP mới | E13: Phiên mobile còn hạn | F13: Cả hai request trả 401 ngay ở request kế tiếp; không cấp session | G13: 401 và 401, không có session | H13: Pass | I13: AC4 · State Transition (đang có phiên → bị xóa) · Decision Table (R3) · test_erased_user_session_and_relogin_rejected__AC4 | K13: ngay_sinh | L13: Từ 1900-01-01 tới hôm nay theo giờ Asia/Ho_Chi_Minh | M13: 11 | N13: Sau hôm nay (giờ VN) Trước 1900-01-01 Ngày không tồn tại hoặc sai định dạng | O13: 29 30 31 | Q13: 422 (invalid_phone / invalid_email / login_identifier_required) | R13: X
A14: TC-LOGIN-06 | B14: Đăng nhập với nhiều cách viết của cùng một số điện thoại | C14: Số thử test_otp | D14: 1. POST /auth/mobile/verify lần lượt với từng dạng số, token 123456 2. So user_id các lần 3. Đếm users có phone_number = +84900000001 | E14: 0900000001 | +84900000001 | +84 900 000 001 | 0900-000-001 | " 0900000001 " | F14: Mọi lần 200 với cùng một user_id; đúng 1 dòng users, phone_number = +84900000001 | G14: 5/5 lần 200, cùng user_id; 1 dòng users | H14: Pass | I14: AC5 · EP (1,2,3) · test_phone_formats_same_user__AC5 | K14: gioi_tinh | L14: nam / nu / khac (không phân biệt hoa thường) | M14: 12 | N14: Giá trị khác, rỗng, chuỗi injection | O14: 32 | Q14: 401 Invalid credentials / không cấp phiên | S14: X | T14: X
A15: TC-LOGIN-07 | B15: Gửi số điện thoại sai định dạng tới OTP và verify | C15: Không | D15: 1. POST /auth/mobile/otp {phone} 2. POST /auth/mobile/verify {phone, token: 123456} 3. Đếm auth.users trước/sau | E15: 84900000001 | (+84)900000001 | 09abc12345 | +84 900\u00a0000 001 | + | 0 | F15: 422 {"detail":"invalid_phone"} ở cả hai endpoint; không tạo user trên Supabase | G15: 422 invalid_phone ở cả 12 request; auth.users không đổi | H15: Pass | I15: AC6 · EP (13,14,16) · test_invalid_phone_rejected_before_provider__AC6 | Q15: 403 admin_must_use_web | U15: X
A16: TC-LOGIN-08 | B16: Gửi số điện thoại có ký tự xuống dòng ở cuối | C16: Số thử test_otp | D16: 1. POST /auth/mobile/otp {phone: "0900000001\n"} 2. POST /auth/mobile/verify {phone: "0900000001\n", token: 123456} | E16: phone: 0900000001 + ký tự \n | F16: 422 {"detail":"invalid_phone"} (theo AC6 của 01-requirement) | G16: OTP 204, verify 200 và cấp phiên (backend bỏ ký tự trắng hai đầu) | H16: Fail | I16: AC6 · Error Guessing · test_invalid_phone_rejected_before_provider__AC6[0900000001\n-*] | Q16: 200, phiên mobile 10 ngày, profile_complete=false | V16: X
A17: TC-LOGIN-09 | B17: Gửi số điện thoại ngay ngoài giới hạn độ dài | C17: Không | D17: 1. POST /auth/mobile/otp và /auth/mobile/verify với từng số | E17: +8490000 (8 ký tự) | +8490000000000000 (17 ký tự) | F17: 422 {"detail":"invalid_phone"} | G17: 422 invalid_phone | H17: Pass | I17: AC6 · BVA (min-1, max+1) · EP (17) · test_invalid_phone_rejected_before_provider__AC6 | Q17: 200, phiên mobile 10 ngày, profile_complete=true | W17: X
A18: TC-LOGIN-10 | B18: Gửi số điện thoại đúng giới hạn độ dài | C18: Không | D18: 1. POST /auth/mobile/otp {phone} 2. POST /auth/mobile/verify {phone, token: 123456} | E18: +84900000 (9 ký tự) | +849000000000000 (16 ký tự) | F18: Không bị backend trả invalid_phone; không 5xx ngoài 503; không lộ nội dung Supabase | G18: Không có invalid_phone; mã trạng thái < 500 hoặc 503; không lộ nội dung | H18: Pass | I18: AC6 · BVA (min, max) · EP (2) · test_phone_length_boundaries_accepted_by_backend__AC6
A19: TC-LOGIN-11 | B19: Gửi số điện thoại viết bằng chữ số Unicode | C19: Không | D19: 1. POST /auth/mobile/otp {phone} 2. POST /auth/mobile/verify {phone, token: 123456} | E19: +８４９０００００００１ (full-width) | +٨٤٩٠٠٠٠٠٠٠١ (chữ số Ả Rập) | F19: 422 {"detail":"invalid_phone"}, không gọi Supabase | G19: OTP 503 {"detail":"auth_provider_unavailable"}, verify 401 {"detail":"Invalid credentials"} — request đã tới Supabase | H19: Fail | I19: AC7 · EP (15) · test_unicode_digit_phone_rejected__AC7
A20: TC-LOGIN-12 | B20: Đăng nhập email với chữ hoa và khoảng trắng hai đầu | C20: Tài khoản email chữ thường user.test+<tag>@example.com | D20: 1. POST /auth/mobile/verify {email: "User.Test+<tag>@Example.COM", token} 2. POST /auth/mobile/verify {email: " user.test+<tag>@example.com ", token mới} 3. Đọc users.email | E20: Hai cách viết của cùng email | F20: Cả hai 200, cùng user_id; users.email lưu chữ thường | G20: 200, 200, cùng user_id; email chữ thường | H20: Pass | I20: AC8 · EP (4,5) · test_email_case_and_spaces_same_user__AC8
A21: TC-LOGIN-13 | B21: Gửi email sai định dạng tới OTP và verify | C21: Không | D21: 1. POST /auth/mobile/otp {email} 2. POST /auth/mobile/verify {email, token: 123456} | E21: abc | a@b | a@@b.com | a b@c.com | @example.com | a@example. | F21: 422 {"detail":"invalid_email"} | G21: 422 invalid_email ở cả 12 request | H21: Pass | I21: AC8 · EP (19) · test_invalid_email_rejected__AC8
A22: TC-LOGIN-14 | B22: Gửi email rỗng hoặc chỉ khoảng trắng, không có số điện thoại | C22: Không | D22: 1. POST /auth/mobile/otp {email} 2. POST /auth/mobile/verify {email, token: 123456} | E22: (blank) | " " | F22: 422 {"detail":"login_identifier_required"} | G22: 422 login_identifier_required | H22: Pass | I22: AC8 · EP (20) · Decision Table (R1) · test_invalid_email_rejected__AC8
A23: TC-LOGIN-15 | B23: Gửi email rất dài và email có dấu tiếng Việt | C23: Không | D23: 1. POST /auth/mobile/otp {email} | E23: a*300@example.com (312 ký tự) | nguyễn@example.com | F23: Không 5xx ngoài 503; không lộ nội dung Supabase | G23: Mã < 500 hoặc 503; không lộ nội dung | H23: Pass | I23: AC8 · Error Guessing · test_long_and_unicode_email_no_5xx__AC8
A24: TC-LOGIN-16 | B24: Xác thực với mã OTP rỗng | C24: Tài khoản email mới | D24: 1. POST /auth/mobile/verify {email, token: ""} | E24: token: (blank) | F24: 422 | G24: 422 | H24: Pass | I24: AC9 · EP (22) · test_empty_token_422__AC9
A25: TC-LOGIN-17 | B25: Xác thực với mã OTP chỉ có khoảng trắng | C25: Tài khoản email mới, chưa có dòng users | D25: 1. POST /auth/mobile/verify {email, token: " "} 2. Đếm users theo email | E25: token: " " | F25: 401; không tạo dòng users | G25: 401; 0 dòng users | H25: Pass | I25: AC9 · EP (23) · test_blank_token_401_no_user__AC9
A26: TC-LOGIN-18 | B26: Xác thực với mã OTP sai độ dài, có chữ hoặc rất dài | C26: Tài khoản email mới, chưa có dòng users | D26: 1. POST /auth/mobile/verify {email, token} cho từng giá trị | E26: 12345 | 1234567 | abcdef | "1"*1000 | F26: 401 hoặc 422; không 5xx; không lộ nội dung; không tạo dòng users | G26: 401/422; không 5xx; 0 dòng users | H26: Pass | I26: AC9 · BVA (min-1, max+1) · EP (24) · test_malformed_tokens_no_5xx__AC9
A27: TC-LOGIN-19 | B27: Gửi trường sai kiểu JSON | C27: Phiên mobile hợp lệ cho /auth/profile | D27: 1. POST /auth/mobile/otp với phone/email là số, mảng, object, true 2. POST /auth/mobile/verify với token sai kiểu 3. POST /auth/profile với ho_ten/gioi_tinh sai kiểu | E27: 900000001 | ["0900000001"] | {"v": "0900000001"} | true | F27: 4xx (422); không 5xx; không lộ chi tiết nội bộ | G27: 422 ở cả 20 request | H27: Pass | I27: AC10 · EP (18) · test_wrong_json_types_no_5xx__AC10
A28: TC-LOGIN-20 | B28: Gửi body hỏng, rỗng hoặc sai Content-Type | C28: Phiên mobile hợp lệ cho /auth/profile | D28: 1. POST tới /auth/mobile/otp, /auth/mobile/verify, /auth/profile với từng loại body | E28: "{not json" | (blank) | text/plain "phone=0900000001" | F28: 4xx; không 5xx | G28: 422 ở cả 9 request | H28: Pass | I28: AC10 · Error Guessing · test_malformed_body_no_5xx__AC10
A29: TC-LOGIN-21 | B29: Gửi field thừa để leo quyền hoặc ghi vào user khác | C29: Tài khoản email mới; một user khác B chưa có hồ sơ | D29: 1. POST /auth/mobile/verify {email, token, system_role: "admin", user_id: <B>} 2. POST /auth/profile (phiên vừa cấp) {hồ sơ hợp lệ, user_id: <B>, system_role: "admin"} 3. Đọc users của mình và của B | E29: system_role: admin; user_id: id của B | F29: Verify 200 với user_id của chính mình; profile 204; system_role vẫn 'user'; hồ sơ chỉ ghi vào mình, B không đổi | G29: Đúng như mong đợi | H29: Pass | I29: AC10 · Error Guessing (leo quyền) · test_extra_fields_have_no_effect__AC10
... A54: TC-LOGIN-46 | B54: Chạy script E2E khi thiếu điều kiện môi trường | C54: Không có Supabase local hoặc không có emulator | D54: 1. backend/.venv/Scripts/python.exe tests/e2e/mobile_login/run_e2e.py | E54: Không | F54: Thoát mã 2 với "LỖI MÔI TRƯỜNG: …"; không chạy flutter, không báo pass; output không chứa key/token/mật khẩu | G54: Đúng như mong đợi (unit test test_run_e2e.py, 16 pass) | H54: Pass | I54: AC21 · test_main_exits_2_when_environment_missing, test_pick_device_*, test_require_local_*, test_redact_* · evidence/test-tests-unit.log
A55: TC-LOGIN-47 | B55: Gõ lại mã OTP bằng bàn phím thật sau khi nhập sai | C55: Điện thoại hoặc emulator, app nối backend có Supabase; đang ở màn OTP sau khi nhập mã sai | D55: 1. Chạm vào ô mã 2. Xóa mã cũ bằng phím xóa 3. Gõ mã đúng bằng bàn phím | E55: Mã đúng của số đang dùng | F55: Mã mới hiện trong ô và app vào Trang chủ | H55: Pending | I55: AC19 · manual · integration_test không gõ lại được vào ô sau khi app bỏ focus nên E2E đặt mã qua controller
A56: TC-LOGIN-48 | B56: Tắt hẳn app (force stop) rồi mở lại khi còn phiên | C56: Đã đăng nhập trên thiết bị | D56: 1. Cài đặt → Ứng dụng → DrugTime → Buộc dừng 2. Mở lại app từ màn hình chính | E56: Không | F56: Vào thẳng Trang chủ, không hỏi OTP | H56: Pending | I56: AC17 · manual · integration_test chỉ dựng lại app trong cùng tiến trình
G59: Pass | H59: =COUNTIF(H9:H56,"Pass")
G60: Fail | H60: =COUNTIF(H9:H56,"Fail")
G61: Pending | H61: =COUNTIF(H9:H56,"Pending")
G62: Total | H62: =SUM(H59:H61)

Sheet Lịch uống thuốc
A1: Project Name | B1: DrugTime
A2: Module Name | B2: Quản lý lịch uống thuốc (SCHED)
A3: Created By | B3: zannguyen
A4: Creation Date | B4: 46304
A5: Reviewed By
A6: Reviewed Date
K7: Equivalence Partitioning | Q7: Kết quả thao tác ghi lịch theo trạng thái thuốc
A8: Test Case ID | B8: Description | C8: Precondition | D8: Test Steps | E8: Test Data | F8: Expected Result | G8: Actual Result | H8: Status | I8: Comments(if any) | K8: Field | L8: Valid | M8: Num | N8: Invalid | O8: Num | Q8: Rule | R8: R1 | S8: R2 | T8: R3 | U8: R4 | V8: R5
A9: TC-SCHED-01 | B9: Thêm giờ uống 12:00 cho thuốc theo giờ | C9: Người bệnh P có consent health_data; thuốc X có lịch 08:00, 20:00 cả tuần | D9: 1. POST /medications/{X}/schedules với body 2. Đọc lịch của X trong DB | E9: {"intake_time": "12:00"} | F9: 201; schedules 08:00, 12:00, 20:00; lịch mới cả tuần, reminder_enabled true, effective_from = thời điểm request; doses_per_day = 3; 08:00, 20:00 giữ id | G9: 201, đúng như kỳ vọng | H9: Pass | I9: AC1 · EP (1) · Decision Table (R5) · test_add_schedule__AC1[None] | K9: intake_time | L9: HH:MM 24 giờ, chưa có lịch mở cùng giờ | M9: 1 | N9: Thiếu Sai định dạng (8:00, 7h, 24:00, 12:60) Trùng giờ một lịch đang mở khác | O9: 7 8 9 | Q9: Thuốc đã ngừng? | R9: Yes | S9: No | T9: No | U9: No | V9: No
A10: TC-SCHED-02 | B10: Thêm giờ uống tắt nhắc | C10: Như TC-SCHED-01 | D10: 1. POST /medications/{X}/schedules với body | E10: {"intake_time": "12:00", "reminder_enabled": false} | F10: 201; lịch 12:00 có reminder_enabled false | G10: 201, reminder_enabled false | H10: Pass | I10: AC1 · EP (2) · test_add_schedule__AC1[False] | K10: reminder_enabled | L10: true false Không gửi (mặc định true khi thêm) | M10: 2 3 4 | N10: Chuỗi "false" null hoặc số 0 | O10: 10 11 | Q10: Thuốc as_needed? | R10: - | S10: Yes | T10: No | U10: No | V10: No
A11: TC-SCHED-03 | B11: Thêm giờ trùng một lịch đang mở | C11: Như TC-SCHED-01 | D11: 1. POST /medications/{X}/schedules với body 2. So dữ liệu thuốc, lịch trước và sau | E11: {"intake_time": "08:00"} | F11: 422 {"detail": "schedule_time_conflict"}; không ghi gì | G11: 422 schedule_time_conflict; DB không đổi | H11: Pass | I11: AC2 · EP (5) · Decision Table (R3) · test_add_schedule_rejected_writes_nothing__AC2 | K11: days_of_week (PATCH /medications/{id}) | L11: 1–7 phần tử, giá trị 1..7, không trùng | M11: 5 | N11: Mảng rỗng Giá trị ngoài 1..7 Phần tử trùng Gửi cho thuốc as_needed | O11: 12 13 14 15 | Q11: Trùng giờ lịch mở? | R11: - | S11: - | T11: Yes | U11: No | V11: No
A12: TC-SCHED-04 | B12: Thêm giờ với body sai cấu trúc | C12: Như TC-SCHED-01 | D12: 1. Gửi lần lượt từng body tới POST /medications/{X}/schedules | E12: {} ; {"intake_time": "24:00"} ; {"intake_time": "08:00", "days_of_week": [1]} ; {"intake_time": "09:00", "foo": 1} | F12: 422, detail là mảng lỗi theo field; không ghi gì | G12: 422 mảng lỗi cho cả 4 body; DB không đổi | H12: Pass | I12: AC2 · EP (3,4) · test_add_schedule_rejected_writes_nothing__AC2 | K12: schedule_id | L12: Lịch đang mở của đúng thuốc | M12: 6 | N12: Lịch đã đóng Lịch của thuốc khác Id không tồn tại | O12: 16 17 18 | Q12: Đã có 6 lịch mở? | R12: - | S12: - | T12: - | U12: Yes | V12: No
A13: TC-SCHED-BVA-01 | B13: Thêm giờ ở biên dưới và trên của ngày | C13: Thuốc có lịch 12:00 | D13: 1. POST /medications/{X}/schedules với 00:00 2. Lặp lại với thuốc khác và 23:59 | E13: 00:00 ; 23:59 | F13: 201 cả hai | G13: 201 cả hai (evidence/testcase-bva-manual.log) | H13: Pass | I13: AC1 · BVA (min, max) · manual (scratch/bva_check.py) | Q13: Action | R13: R1 | S13: R2 | T13: R3 | U13: R4 | V13: R5
A14: TC-SCHED-BVA-02 | B14: Thêm giờ ở biên trên + 1 | C14: Như TC-SCHED-01 | D14: 1. POST /medications/{X}/schedules | E14: {"intake_time": "24:00"} | F14: 422 mảng lỗi | G14: 422 mảng lỗi | H14: Pass | I14: AC2 · BVA (max+1) · test_add_schedule_rejected_writes_nothing__AC2; test_schedule_structural_errors_422_array | Q14: 422 medication_stopped | R14: X
A15: TC-SCHED-BVA-03 | B15: Thêm lịch thứ 6 (biên trên số lịch) | C15: Thuốc có 5 lịch mở | D15: 1. POST /medications/{X}/schedules 16:00 | E15: {"intake_time": "16:00"} | F15: 201; doses_per_day = 6 | G15: 201; doses_per_day 6 (evidence/testcase-bva-manual.log) | H15: Pass | I15: AC2 · BVA (max) · manual (scratch/bva_check.py) | Q15: 422 medication_rule_violation | S15: X
A16: TC-SCHED-BVA-04 | B16: Thêm lịch thứ 7 (biên trên + 1) | C16: Thuốc có 6 lịch mở | D16: 1. POST /medications/{X}/schedules 18:00 | E16: {"intake_time": "18:00"} | F16: 422 {"detail": "schedule_limit_reached"}; không ghi gì | G16: 422 schedule_limit_reached; lịch không đổi | H16: Pass | I16: AC2 · BVA (max+1) · Decision Table (R4) · test_add_schedule_limit_reached__AC2 | Q16: 422 schedule_time_conflict | T16: X
A17: TC-SCHED-05 | B17: Thêm giờ cho thuốc dùng khi cần | C17: Thuốc W as_needed | D17: 1. POST /medications/{W}/schedules | E17: {"intake_time": "08:00"} | F17: 422 {"detail": "medication_rule_violation"}; không có lịch | G17: 422 medication_rule_violation | H17: Pass | I17: AC2 · Decision Table (R2) · test_add_schedule_as_needed_422__AC2 | Q17: 422 schedule_limit_reached | U17: X
A18: TC-SCHED-06 | B18: Ghi lịch của thuốc đã ngừng | C18: Thuốc X đã ngừng (PATCH stopped true) | D18: 1. POST /medications/{X}/schedules 2. PATCH /medications/{X}/schedules/{S1} 3. DELETE /medications/{X}/schedules/{S1} | E18: 12:00 ; {"intake_time": "07:00"} ; (blank) | F18: Cả ba 422 {"detail": "medication_stopped"}; không ghi gì | G18: 422 medication_stopped cả ba; DB không đổi | H18: Pass | I18: AC8 · Decision Table (R1) · test_stopped_medication_schedule_writes_422__AC8 | Q18: 201, thêm lịch | V18: X
A19: TC-SCHED-07 | B19: Đổi giờ một lịch, lịch cũ đóng chứ không xoá | C19: X có S1 08:00, S2 20:00; một liều quá khứ trỏ S1 | D19: 1. PATCH /medications/{X}/schedules/{S1} 2. Đọc lịch và dose_logs trong DB | E19: {"intake_time": "07:00"} | F19: 200; S1 có ended_at, vẫn còn dòng; lịch 07:00 id mới, effective_from = ended_at(S1), giữ ngày và nhắc; S2 không đổi; doses_per_day 2; liều cũ vẫn trỏ S1 | G19: 200, đúng như kỳ vọng | H19: Pass | I19: AC3 · test_edit_time_versions_schedule_and_keeps_dose_logs__AC3
A20: TC-SCHED-08 | B20: Tắt rồi bật nhắc một giờ | C20: Như TC-SCHED-07 | D20: 1. PATCH S1 reminder_enabled false 2. PATCH lịch mới reminder_enabled true | E20: {"reminder_enabled": false} ; {"reminder_enabled": true} | F20: Mỗi lần 200, đóng lịch cũ và tạo lịch 08:00 id mới với trạng thái nhắc mới; luôn còn 2 lịch mở | G20: 200 cả hai; 2 lịch mở, 4 dòng lịch | H20: Pass | I20: AC4 · EP (1,2) · test_toggle_reminder_versions_schedule__AC4
A21: TC-SCHED-09 | B21: Sửa lịch với giá trị giống hiện tại | C21: S2 20:00 nhắc bật | D21: 1. PATCH /medications/{X}/schedules/{S2} với từng body | E21: {"reminder_enabled": true} ; {"intake_time": "20:00"} ; cả hai | F21: 200; S2 giữ id; DB không đổi | G21: 200; DB không đổi | H21: Pass | I21: AC4 · test_edit_same_values_noop__AC4
A22: TC-SCHED-10 | B22: Sửa lịch sang giờ trùng lịch khác hoặc body sai | C22: Như TC-SCHED-07 | D22: 1. PATCH /medications/{X}/schedules/{S1} với từng body | E22: {"intake_time": "20:00"} ; {} ; {"intake_time": "7h"} ; {"reminder_enabled": false, "x": 1} | F22: 422 (schedule_time_conflict cho body đầu, mảng lỗi cho phần còn lại); không ghi gì | G22: Đúng như kỳ vọng | H22: Pass | I22: AC5 · EP (5,3) · test_edit_invalid_writes_nothing__AC5
A23: TC-SCHED-11 | B23: Sửa hoặc hủy lịch đã đóng, lịch thuốc khác, id không tồn tại | C23: S1 đã bị thay (sau TC-SCHED-07); P có thuốc khác Y | D23: 1. PATCH và DELETE /medications/{X}/schedules/{id} với từng id | E23: S1 (đã đóng) ; lịch của Y ; 4611686018427387904 | F23: 404 {"detail": "medication_schedule_not_found"}; không lịch nào đổi | G23: 404 cả 6 lần; DB không đổi | H23: Pass | I23: AC6 · EP (schedule_id: không hợp lệ) · test_closed_or_foreign_schedule_404_changes_nothing__AC6
A24: TC-SCHED-12 | B24: Hủy một giờ uống | C24: X có S1, S2 | D24: 1. DELETE /medications/{X}/schedules/{S2} 2. GET /medications/{X} | E24: (blank) | F24: 200; schedules chỉ còn S1; S2 có ended_at; doses_per_day 1; liều không đổi | G24: 200, đúng như kỳ vọng | H24: Pass | I24: AC7 · test_remove_schedule__AC7
A25: TC-SCHED-13 | B25: Hủy lịch mở cuối cùng | C25: X chỉ còn S1 | D25: 1. DELETE /medications/{X}/schedules/{S1} | E25: (blank) | F25: 422 {"detail": "last_schedule_not_removable"}; lịch vẫn mở | G25: 422 last_schedule_not_removable | H25: Pass | I25: AC8 · test_remove_last_schedule_422__AC8
A26: TC-SCHED-14 | B26: Đổi ngày uống trong tuần | C26: X có S1 08:00 nhắc bật, S2 20:00 nhắc tắt | D26: 1. PATCH /medications/{X} 2. Gửi lại cùng ngày 3. PATCH kèm intake_times | E26: {"days_of_week": [5,1,3]} ; [1,3,5] ; {"intake_times": ["09:00"], "days_of_week": [6,7]} | F26: Lần 1: 200, lịch mới 08:00 và 20:00 ngày [1,3,5], giữ nhắc, cùng effective_from = ended_at lịch cũ; lần 2: không đổi lịch; lần 3: lịch 09:00 ngày [6,7] | G26: Đúng như kỳ vọng | H26: Pass | I26: AC9 · EP (days: hợp lệ) · test_patch_days_of_week__AC9
A27: TC-SCHED-15 | B27: Đổi ngày uống với giá trị sai | C27: Như TC-SCHED-14 | D27: 1. PATCH /medications/{X} với từng body | E27: [] ; [8] ; [1,1] ; chuyển sang as_needed kèm days_of_week [1] | F27: 422 (mảng lỗi, hoặc medication_rule_violation cho body cuối); không ghi gì | G27: Đúng như kỳ vọng | H27: Pass | I27: AC9 · EP (days: không hợp lệ) · test_patch_days_invalid_writes_nothing__AC9; test_patch_days_on_as_needed_422__AC9
A28: TC-SCHED-BVA-05 | B28: Đổi ngày uống ở biên 1, 7 và 0, 8 | C28: Thuốc có lịch 08:00 | D28: 1. PATCH /medications/{X} với từng giá trị | E28: [1] ; [7] ; [0] ; [8] | F28: [1], [7]: 200; [0], [8]: 422 | G28: 200, 200, 422, 422 (evidence/testcase-bva-manual.log) | H28: Pass | I28: AC9 · BVA (min, max, min-1, max+1) · manual (scratch/bva_check.py)
A29: TC-SCHED-16 | B29: Đổi giờ qua PATCH /medications giữ trạng thái nhắc | C29: S2 20:00 đang tắt nhắc | D29: 1. PATCH /medications/{X} | E29: {"intake_times": ["08:00","20:00","22:00"]} | F29: 08:00 bật, 20:00 tắt, 22:00 bật | G29: Đúng như kỳ vọng | H29: Pass | I29: AC10 · test_patch_times_keeps_reminder__AC10
A30: TC-SCHED-17 | B30: Hai request thêm cùng giờ gửi đồng thời | C30: Như TC-SCHED-01 | D30: 1. Gửi song song hai POST /medications/{X}/schedules 12:00 | E30: {"intake_time": "12:00"} ×2 | F30: Một 201, một 422; đúng một lịch 12:00 mở; doses_per_day = số lịch mở | G30: [201, 422]; một lịch 12:00 (5/5 lần lặp) | H30: Pass | I30: AC11 · đoán lỗi (gửi trùng) · test_two_adds_same_time_one_wins__AC11
... A48: TC-SCHED-35 | B48: Giữ bất biến lịch trên chuỗi thao tác ngẫu nhiên có seed cố định | C48: Mỗi chuỗi: một thuốc theo giờ mới tạo (08:00, 20:00) | D48: 1. Chạy 10 bước ngẫu nhiên theo seed: thêm/sửa/xóa từng lịch, bật/tắt nhắc, đổi giờ, đổi ngày, ngừng, dùng lại, chuyển chế độ, ghi liều xác nhận sớm 2. Sau mỗi bước kiểm bất biến I1–I5 | E48: Seed 0–49 và 96, 97, 178, 198 (gồm 5 seed đã tìm ra R3: 43, 96, 97, 178, 198) | F48: I1 không giờ dự kiến thuộc hai lịch; I2 liều trong khoảng của lịch nó trỏ tới; I3 thuốc khi cần/đã ngừng không có lịch mở; I4 doses_per_day = số lịch mở, giờ không trùng; I5 không 5xx | G48: 54/54 chuỗi giữ bất biến (bản 200 seed ở implement: 200/200; trước khi sửa R3: 195/200) | H48: Pass | I48: AC30 · Chuyển trạng thái (ngẫu nhiên) · test_random_sequences_keep_invariants__AC30
G51: Pass | H51: =COUNTIF(H9:H48,"Pass")
G52: Fail | H52: =COUNTIF(H9:H48,"Fail")
G53: Pending | H53: =COUNTIF(H9:H48,"Pending")
G54: Total | H54: =SUM(H51:H53)

Sheet Tải lịch uống
A1: Project Name | B1: DrugTime
A2: Module Name | B2: Tải lịch uống và phân quyền dữ liệu thuốc (SCHEDSYNC)
A3: Created By | B3: zannguyen
A4: Creation Date | B4: 46304
A5: Reviewed By
A6: Reviewed Date
K7: Equivalence Partitioning | Q7: Quyền đọc GET /patients/{patient_id}/schedules
A8: Test Case ID | B8: Description | C8: Precondition | D8: Test Steps | E8: Test Data | F8: Expected Result | G8: Actual Result | H8: Status | I8: Comments(if any) | K8: Field | L8: Valid | M8: Num | N8: Invalid | O8: Num | Q8: Rule | R8: R1 | S8: R2 | T8: R3 | U8: R4 | V8: R5 | W8: R6
A9: TC-SCHEDSYNC-01 | B9: Người bệnh tải lịch của chính mình | C9: P có X (S1, S2 mở; S0 đóng 10 ngày trước; S9 đóng 40 ngày trước), Y đã ngừng, Z đã xoá, W khi cần; người khác có thuốc | D9: 1. GET /patients/{P}/schedules | E9: (không query) | F9: 200; items gồm S1, S2, S0, lịch của Y, sắp theo id; không có S9, Z, W, người khác; mỗi phần tử đủ 11 field, ended_at null khi mở; next_cursor null; không ghi access_logs | G9: Đúng như kỳ vọng | H9: Pass | I9: AC12 · Decision Table (R1) · test_patient_reads_own_schedules__AC12 | K9: limit | L9: 1..200 Không gửi (mặc định 100) | M9: 1 2 | N9: 0 201 Không phải số | O9: 5 6 7 | Q9: Người gọi là chính người bệnh? | R9: Yes | S9: Yes | T9: No | U9: No | V9: No | W9: No
A10: TC-SCHEDSYNC-02 | B10: Người bệnh chưa có lịch nào | C10: P không có thuốc | D10: 1. GET /patients/{P}/schedules | E10: (blank) | F10: 200 {"items": [], "next_cursor": null} | G10: Đúng như kỳ vọng | H10: Pass | I10: AC12 · test_patient_without_schedules_gets_empty_page__AC12 | K10: cursor | L10: next_cursor của trang trước, cùng người bệnh | M10: 3 | N10: Chuỗi rác Base64 không phải JSON hợp lệ Con trỏ của người bệnh khác Chuỗi rỗng | O10: 8 9 10 11 | Q10: Consent health_data còn hiệu lực? | R10: Yes | S10: No | T10: Yes | U10: Yes | V10: No | W10: Yes
A11: TC-SCHEDSYNC-03 | B11: Tải theo trang với limit 2 | C11: P có 5 lịch | D11: 1. GET limit=2 2. Gửi next_cursor cho tới khi null | E11: limit=2 | F11: 3 trang (2, 2, 1); hợp các trang bằng kết quả không phân trang | G11: 3 trang, đúng thứ tự | H11: Pass | I11: AC23 · EP (limit: hợp lệ; cursor: hợp lệ) · test_pagination__AC23 | K11: patient_id | L11: UUID của tài khoản tồn tại | M11: 4 | N11: Không phải UUID UUID không có tài khoản | O11: 12 13 | Q11: Liên kết active + bật chia sẻ + consent family_sharing? | R11: - | S11: - | T11: Yes | U11: No | V11: Yes | W11: No
A12: TC-SCHEDSYNC-BVA-01 | B12: limit ở biên 1 và 200 | C12: P có 2 lịch | D12: 1. GET limit=1 2. GET limit=200 | E12: 1 ; 200 | F12: 200; limit 1 trả 1 lịch và có next_cursor; limit 200 trả 2 lịch, next_cursor null | G12: Đúng như kỳ vọng (evidence/testcase-bva-manual.log) | H12: Pass | I12: AC23 · BVA (min, max) · manual (scratch/bva_check.py) | Q12: Người gọi là admin? | R12: - | S12: - | T12: - | U12: No | V12: - | W12: Yes
A13: TC-SCHEDSYNC-BVA-02 | B13: limit ở biên 0 và 201 | C13: P bất kỳ | D13: 1. GET limit=0 2. GET limit=201 | E13: 0 ; 201 | F13: 422 mảng lỗi | G13: 422 cả hai | H13: Pass | I13: AC23 · BVA (min-1, max+1) · test_limit_out_of_range_422__AC23 | Q13: Action | R13: R1 | S13: R2 | T13: R3 | U13: R4 | V13: R5 | W13: R6
A14: TC-SCHEDSYNC-04 | B14: Con trỏ hỏng hoặc của người bệnh khác | C14: P bất kỳ | D14: 1. GET với từng cursor | E14: !!! ; abc ; eyJhIjoxfQ ; con trỏ mã hoá cho UUID khác | F14: 422 {"detail": "invalid_cursor"} | G14: 422 invalid_cursor cả 4 | H14: Pass | I14: AC23 · EP (cursor: không hợp lệ) · test_bad_cursor_422__AC23; test_cursor_of_other_patient_422__AC23 | Q14: 200, không ghi log | R14: X
A15: TC-SCHEDSYNC-05 | B15: Người thân hợp lệ tải lịch qua nhiều trang | C15: F có liên kết active, bật chia sẻ; P có consent health_data, family_sharing | D15: 1. F GET limit=2 tới trang cuối | E15: limit=2 | F15: 200 mọi trang; mỗi trang một dòng access_logs allowed, actor_role family | G15: Đúng như kỳ vọng | H15: Pass | I15: AC13 · Decision Table (R3) · test_family_allowed_logged_each_page__AC13 | Q15: 403 consent_revoked | S15: X
A16: TC-SCHEDSYNC-06 | B16: Admin tải lịch của người bệnh (QD-32) | C16: Admin không có liên kết với P | D16: 1. Admin GET /patients/{P}/schedules | E16: (blank) | F16: 403 {"detail": "khong_co_quyen"}; access_logs denied, actor_role admin | G16: Đúng như kỳ vọng | H16: Pass | I16: AC13 · AC22 · Decision Table (R6) · test_admin_denied_logged__AC13 | Q16: 200 + access_logs allowed (family) | T16: X
A17: TC-SCHEDSYNC-07 | B17: Người lạ tải lịch của người bệnh | C17: Q không có liên kết với P | D17: 1. Q GET /patients/{P}/schedules | E17: (blank) | F17: 403 khong_co_quyen; không lộ items; access_logs denied (actor Q, patient P, scope danh_sach_thuoc) | G17: Đúng như kỳ vọng | H17: Pass | I17: AC13 · Decision Table (R4) · kịch bản 'truy cập chéo khi không có liên kết' · test_unlinked_user_denied_logged__AC13 | Q17: 403 khong_co_quyen + access_logs denied | U17: X | V17: X | W17: X
A18: TC-SCHEDSYNC-08 | B18: Người thân thiếu consent hoặc bị tắt chia sẻ | C18: Liên kết có một trong: tắt chia sẻ, thiếu family_sharing, thiếu health_data | D18: 1. F GET /patients/{P}/schedules | E18: 3 trường hợp | F18: 403; một dòng denied khong_co_quyen | G18: Đúng như kỳ vọng cả 3 | H18: Pass | I18: AC13 · Decision Table (R4, R5) · test_family_missing_consent_or_sharing_off_denied
A19: TC-SCHEDSYNC-09 | B19: Người thân đổi patient_id sang người bệnh khác | C19: F liên kết với P, không liên kết với R | D19: 1. F GET /patients/{R}/schedules | E19: patient_id = R | F19: 403; dòng denied ghi cho R; không có log cho P | G19: Đúng như kỳ vọng | H19: Pass | I19: Cross-patient · test_family_swaps_patient_id_denied
A20: TC-SCHEDSYNC-10 | B20: Rút quyền giữa hai trang | C20: F đã tải trang 1 | D20: 1. Rút health_data / family_sharing / tắt chia sẻ / hủy liên kết 2. F gửi trang 2 với next_cursor | E20: 4 trường hợp | F20: Trang 2 trả 403; nhật ký: allowed rồi denied | G20: Đúng như kỳ vọng cả 4 | H20: Pass | I20: AC14 · kịch bản 'rút consent hoặc hủy liên kết → 403 ngay' · test_revoke_between_pages_403__AC14
A21: TC-SCHEDSYNC-11 | B21: Ghi access log thất bại khi người thân đọc | C21: Giả lập lỗi ghi access_logs allowed | D21: 1. F GET /patients/{P}/schedules | E21: append_allowed ném lỗi | F21: 500; response không chứa dữ liệu lịch | G21: 500, không có dữ liệu | H21: Pass | I21: Fail-closed · test_allowed_log_failure_fails_request
A22: TC-SCHEDSYNC-12 | B22: Người thân, admin, người lạ gọi endpoint ghi lịch | C22: X của P | D22: 1. POST schedules 2. PATCH schedule 3. DELETE schedule 4. PATCH /medications/{X} days_of_week | E22: 3 vai × 4 endpoint | F22: 403 khong_co_quyen cả 4; 4 dòng denied với vai thực tế; X không đổi | G22: Đúng như kỳ vọng | H22: Pass | I22: AC15 · test_write_endpoints_denied_for_family_admin_stranger__AC15
A23: TC-SCHEDSYNC-13 | B23: Người bệnh đã rút consent health_data ghi hoặc đọc lịch | C23: P rút health_data | D23: 1. Gọi 4 endpoint ghi 2. GET /patients/{P}/schedules | E23: (blank) | F23: 403 {"detail": "consent_revoked"}; không ghi gì | G23: Đúng như kỳ vọng | H23: Pass | I23: AC15 · Decision Table (R2) · test_self_revoked_consent_cannot_write__AC15
A24: TC-SCHEDSYNC-14 | B24: patient_id không ứng với tài khoản nào | C24: Người dùng thường hoặc admin | D24: 1. GET /patients/{UUID ngẫu nhiên}/schedules | E24: uuid4 chưa có | F24: 403 khong_co_quyen; không có dòng access_logs; không 5xx | G24: Đúng như kỳ vọng cả hai vai | H24: Pass | I24: AC16 · EP (patient_id: UUID không có tài khoản) · test_unknown_patient_403_without_log__AC16
A25: TC-SCHEDSYNC-15 | B25: Gọi không có token hoặc token sai; thuốc đã xoá | C25: X của P | D25: 1. Gọi 4 endpoint không có header và với 'Bearer x' 2. Xoá X rồi gọi 3 endpoint ghi lịch | E25: (blank) ; Bearer x | F25: 401 khi thiếu hoặc sai token; 404 user_medication_not_found khi thuốc đã xoá | G25: Đúng như kỳ vọng | H25: Pass | I25: AC16 · test_unauthenticated_401_and_unknown_medication_404__AC16
A26: TC-SCHEDSYNC-16 | B26: patient_id sai định dạng | C26: Đã đăng nhập | D26: 1. GET /patients/abc/schedules | E26: abc | F26: 422 mảng lỗi | G26: 422 mảng lỗi | H26: Pass | I26: AC16 · EP (patient_id: không phải UUID) · tests/unit test_patient_id_must_be_uuid
A27: TC-SCHEDSYNC-17 | B27: Admin xem một thuốc của người bệnh (QD-32) | C27: X của P; admin không có liên kết | D27: 1. Admin GET /medications/{X} 2. Admin PATCH /medications/{X} | E27: {"quantity_per_dose": 3} | F27: 403 cả hai; 2 dòng denied actor_role admin | G27: Đúng như kỳ vọng | H27: Pass | I27: AC22 · test_admin_get_medication_403_denied__AC22; test_admin_cannot_read_or_write__AC15_QD32
A28: TC-SCHEDSYNC-18 | B28: Admin xác nhận liều hộ (QD-32) | C28: Lịch S1 của P; admin không có liên kết | D28: 1. Admin POST /doses/batch với một liều của S1 | E28: schedule_id = S1, scheduled_at = 5 phút trước | F28: 200; item result failed, http_status 403; không có dose_logs; access_logs denied admin, scope lich_su_tuan_thu | G28: Đúng như kỳ vọng | H28: Pass | I28: AC22 · test_admin_dose_batch_rejected__AC22
A29: TC-SCHEDSYNC-19 | B29: App người thân không lưu lịch xuống máy (QD-29) | C29: App mobile của người thân đã nối GET /patients/{id}/schedules | D29: 1. Người thân mở lịch của người bệnh 2. Tắt mạng, đóng và mở lại app 3. Kiểm tra CSDL cục bộ | E29: (blank) | F29: Không có lịch của người bệnh trong CSDL cục bộ; chỉ giữ trong phiên | H29: Pending | I29: QD-29 · manual · cần app mobile (chưa có task nối API)
G32: Pass | H32: =COUNTIF(H9:H29,"Pass")
G33: Fail | H33: =COUNTIF(H9:H29,"Fail")
G34: Pending | H34: =COUNTIF(H9:H29,"Pending")
G35: Total | H35: =SUM(H32:H34)

Sheet Tương tác thuốc-thuốc
A1: Project Name | B1: DrugTime
A2: Module Name | B2: Danh mục tương tác thuốc-thuốc (admin) (DDIRULE)
A3: Created By | B3: zannguyen
A4: Creation Date | B4: 46307
A5: Reviewed By
A6: Reviewed Date
K7: Equivalence Partitioning | Q7: Quyền gọi endpoint /admin/drug-interactions
A8: Test Case ID | B8: Description | C8: Precondition | D8: Test Steps | E8: Test Data | F8: Expected Result | G8: Actual Result | H8: Status | I8: Comments(if any) | K8: Field | L8: Valid | M8: Num | N8: Invalid | O8: Num | Q8: Rule | R8: R1 | S8: R2 | T8: R3
A9: TC-DDIRULE-01 | B9: Tạo quy tắc chống chỉ định giữa hai hoạt chất trong danh mục | C9: Đăng nhập admin (phiên admin_web); hoạt chất X, Y có trong danh mục | D9: 1. POST /admin/drug-interactions với A = X, B = Y, chong_chi_dinh, mức 4, tranh_phoi_hop, mô tả, nguồn 2. Kiểm dòng DB của phiên bản vừa tạo | E9: {ingredient_a_id: X, ingredient_b_id: Y, interaction_type: chong_chi_dinh, severity_level: 4, handling_type: tranh_phoi_hop} | F9: 201; version = 1, state = current; ingredient_a/ingredient_b có id và standard_name; verification_status = da_xac_minh; updated_by.id = admin. DB: ingredient_b_in_table_a = co, deleted_at rỗng, created_by = admin | G9: 201 và các giá trị đúng như mong đợi | H9: Pass | I9: AC1 · EP (1) · test_create_with_catalog_ingredient_b__AC1 | K9: Hoạt chất B | L9: ingredient_b_id có trong danh mục, khác A ingredient_b_external_name (chất ngoài danh mục) | M9: 1 2 | N9: gửi cả hai không gửi cả hai id không tồn tại B trùng A | O9: 9 10 11 12 | Q9: Có token hợp lệ? | R9: No | S9: Yes | T9: Yes
A10: TC-DDIRULE-02 | B10: Tạo quy tắc với hoạt chất B là chất ngoài danh mục | C10: Admin; hoạt chất X có trong danh mục | D10: 1. POST /admin/drug-interactions với ingredient_b_external_name = "Rượu", không gửi ingredient_b_id | E10: ingredient_b_external_name: Rượu | F10: 201; ingredient_b = null, ingredient_b_external_name = Rượu; DB: ingredient_b_id rỗng, ingredient_b_in_table_a = khong | G10: 201, DB đúng như mong đợi | H10: Pass | I10: AC2 · EP (2) · test_create_with_external_ingredient_b__AC2 | K10: severity_level | L10: 1–4 | M10: 3 | N10: < 1 > 4 chong_chi_dinh mà khác 4 | O10: 13 14 15 | Q10: system_role = admin? | R10: - | S10: No | T10: Yes
A11: TC-DDIRULE-03 | B11: Tạo, thay và giữ ngưỡng liều của quy tắc phụ thuộc liều | C11: Admin; hoạt chất X, Y | D11: 1. POST với 2 ngưỡng (A 0–100 mg/ngày mức 2; B ≥300 mg/ngày mức 4) 2. GET /admin/drug-interactions/{id} 3. PATCH gửi dose_thresholds 1 ngưỡng (A 50–60) 4. PATCH chỉ đổi description | E11: dose_thresholds như bước | F11: GET trả đủ 2 ngưỡng; sau PATCH thứ nhất chỉ còn ngưỡng 50–60; sau PATCH thứ hai ngưỡng giữ nguyên | G11: Đúng như mong đợi | H11: Pass | I11: AC3 · test_dose_thresholds_create_replace_keep__AC3 | K11: min_interval_hours | L11: null 0 < số giờ ≤ 168 với cach_gio | M11: 4 5 | N11: ≤ 0 > 168 có giá trị mà handling_type khác cach_gio | O11: 16 17 18 | Q11: Action | R11: R1 | S11: R2 | T11: R3
A12: TC-DDIRULE-04 | B12: Từ chối tạo quy tắc có A trùng B | C12: Admin; hoạt chất X | D12: 1. POST với ingredient_a_id = ingredient_b_id = X 2. Đếm quy tắc và ngưỡng chạm X | E12: A = B = X | F12: 422 {"detail": "same_ingredient"}; không có dòng mới | G12: 422 same_ingredient; số dòng không đổi | H12: Pass | I12: AC4 · EP (12) · test_validation_errors_write_nothing__AC4 | K12: dose_thresholds | L12: 0–20 ngưỡng hợp lệ với phu_thuoc_lieu | M12: 6 | N12: > 20 ngưỡng min_dose > max_dose thiếu cả min và max liều âm ingredient_ref = B khi B ngoài danh mục có ngưỡng với chong_chi_dinh | O12: 19 20 21 22 23 24 | Q12: 401 | R12: X
A13: TC-DDIRULE-05 | B13: Từ chối tạo quy tắc với id hoạt chất không tồn tại | C13: Admin | D13: 1. POST với ingredient_b_id = 2000000000 | E13: ingredient_b_id: 2000000000 | F13: 422 {"detail": "active_ingredient_not_found"}; không có dòng mới | G13: 422 active_ingredient_not_found | H13: Pass | I13: AC4 · EP (11) · test_validation_errors_write_nothing__AC4 | K13: verification_status (request) | L13: không gửi | M13: 7 | N13: gửi bất kỳ giá trị | O13: 25 | Q13: 403 admin_only, không ghi gì | S13: X
A14: TC-DDIRULE-06 | B14: Từ chối gửi cả ingredient_b_id và ingredient_b_external_name | C14: Admin; X, Y | D14: 1. POST với cả ingredient_b_id = Y và ingredient_b_external_name = Rượu | E14: cả hai field B | F14: 422 ValidationError (detail là mảng lỗi theo field); không có dòng mới | G14: 422 ValidationError | H14: Pass | I14: AC4 · EP (9) · test_validation_errors_write_nothing__AC4 | K14: expected_version (PATCH/DELETE) | L14: bằng phiên bản hiện hành | M14: 8 | N14: phiên bản cũ thiếu | O14: 26 27 | Q14: Xử lý theo nghiệp vụ | T14: X
A15: TC-DDIRULE-07 | B15: Từ chối không gửi hoạt chất B | C15: Admin; X | D15: 1. POST không có ingredient_b_id lẫn ingredient_b_external_name | E15: thiếu B | F15: 422 ValidationError | G15: 422 ValidationError | H15: Pass | I15: AC4 · EP (10) · test_create_without_b_422 (unit)
A16: TC-DDIRULE-08 | B16: Từ chối chống chỉ định với mức độ khác 4 | C16: Admin; X, Y | D16: 1. POST interaction_type = chong_chi_dinh, severity_level = 2 | E16: chong_chi_dinh, mức 2 | F16: 422 {"detail": "contraindication_severity_mismatch"} | G16: 422 contraindication_severity_mismatch | H16: Pass | I16: AC4 · EP (15) · test_validation_errors_write_nothing__AC4
A17: TC-DDIRULE-09 | B17: Từ chối chống chỉ định kèm ngưỡng liều | C17: Admin; X, Y | D17: 1. POST chong_chi_dinh, mức 4, có 1 ngưỡng | E17: chong_chi_dinh + dose_thresholds[1] | F17: 422 {"detail": "threshold_not_allowed"} | G17: 422 threshold_not_allowed | H17: Pass | I17: AC4 · EP (24) · test_validation_errors_write_nothing__AC4 | Q17: Kết quả PATCH theo phiên bản và nội dung
A18: TC-DDIRULE-10 | B18: Từ chối ngưỡng có min_dose lớn hơn max_dose | C18: Admin; X, Y | D18: 1. POST với ngưỡng min_dose = 100, max_dose = 50 | E18: min 100, max 50 | F18: 422 {"detail": "threshold_range_invalid"} | G18: 422 threshold_range_invalid | H18: Pass | I18: AC4 · EP (20) · test_validation_errors_write_nothing__AC4 | Q18: Rule | R18: R1 | S18: R2 | T18: R3 | U18: R4
A19: TC-DDIRULE-11 | B19: Từ chối ngưỡng thiếu cả min_dose và max_dose | C19: Admin; X, Y | D19: 1. POST với ngưỡng không có min_dose, max_dose | E19: ngưỡng không có khoảng liều | F19: 422 ValidationError | G19: 422 ValidationError | H19: Pass | I19: AC4 · EP (21) · test_validation_errors_write_nothing__AC4 | Q19: Quy tắc tồn tại, chưa xóa? | R19: No | S19: Yes | T19: Yes | U19: Yes
A20: TC-DDIRULE-12 | B20: Từ chối ngưỡng có liều âm | C20: Admin; X, Y | D20: 1. POST với ngưỡng min_dose = -1 | E20: min_dose: -1 | F20: 422 ValidationError | G20: 422 ValidationError | H20: Pass | I20: AC4 · EP (22) · test_create_structure_errors_422 (unit) | Q20: expected_version = hiện hành? | R20: - | S20: No | T20: Yes | U20: Yes
A21: TC-DDIRULE-13 | B21: Từ chối ngưỡng cho hoạt chất B khi B là chất ngoài danh mục | C21: Admin; X | D21: 1. POST B = Rượu (tên ngoài), ngưỡng ingredient_ref = B 2. Đếm dòng chạm X | E21: ingredient_ref: B | F21: 422 {"detail": "threshold_ref_invalid"}; không có dòng mới | G21: 422 threshold_ref_invalid; 0 dòng | H21: Pass | I21: AC4 · EP (23) · test_threshold_for_external_b_rejected__AC4 | Q21: Nội dung khác hiện hành? | R21: - | S21: - | T21: No | U21: Yes
A22: TC-DDIRULE-14 | B22: Từ chối gửi verification_status khi tạo và khi sửa | C22: Admin; X, Y | D22: 1. POST có verification_status = cho_duyet 2. Tạo quy tắc hợp lệ rồi PATCH có verification_status 3. Đọc verification_status trong DB | E22: verification_status: cho_duyet / x | F22: Cả hai 422 ValidationError; DB chỉ có da_xac_minh | G22: 422 cả hai; DB = [da_xac_minh] | H22: Pass | I22: AC15, AC16 · EP (25) · test_verification_status_not_writable__AC15_AC16 | Q22: Action | R22: R1 | S22: R2 | T22: R3 | U22: R4
A23: TC-DDIRULE-15 | B23: Báo trùng khi tạo cặp hoạt chất đảo thứ tự hoặc tên ngoài khác hoa thường | C23: Admin; đã có quy tắc (X, Y) và (X, "Rượu") | D23: 1. POST (Y, X) 2. POST (X, "rượu") | E23: cặp đảo chiều; tên ngoài viết thường | F23: 409 {"detail": "interaction_rule_exists"} cho cả hai; không có dòng mới | G23: 409 interaction_rule_exists; vẫn 2 quy tắc | H23: Pass | I23: AC5 · Đoán lỗi · test_duplicate_pair_conflict__AC5 | Q23: 404 interaction_rule_not_found | R23: X
A24: TC-DDIRULE-16 | B24: Hai request tạo cùng cặp chạy đồng thời chỉ một thành công | C24: Admin; X, Y chưa có quy tắc; một giao dịch khác đang giữ cặp (X, Y) chưa commit | D24: 1. Gửi đồng thời POST (X, Y) và POST (Y, X) 2. Chờ tới khi cả hai đang chờ khóa DB 3. Rollback giao dịch đang giữ 4. Đếm quy tắc mở của cặp | E24: 2 request song song | F24: Một 201, một 409; đúng 1 quy tắc mở cho cặp | G24: [201, 409]; 1 quy tắc | H24: Pass | I24: AC6 · Chạy đua · test_concurrent_create_one_wins__AC6 | Q24: 409 version_conflict | S24: X
A25: TC-DDIRULE-17 | B25: Xóa mềm quy tắc: ẩn khỏi danh sách, giữ dòng và ngưỡng, tạo lại được | C25: Admin; quy tắc Q (phiên bản 1, 1 ngưỡng) | D25: 1. DELETE /admin/drug-interactions/{id}?expected_version=1 2. Kiểm DB 3. GET, PATCH, DELETE lại Q 4. GET danh sách lọc theo X 5. POST lại cùng cặp | E25: expected_version: 1 | F25: 204 rỗng; DB còn dòng, deleted_at và deleted_by = admin, ngưỡng còn; GET/PATCH/DELETE 404 interaction_rule_not_found; danh sách rỗng; tạo lại 201 với mã mới | G25: Đúng như mong đợi | H25: Pass | I25: AC7, AC24 · Chuyển trạng thái (current → deleted) · test_soft_delete_hides_keeps_rows_and_allows_recreate__AC7 | Q25: 200, giữ phiên bản | T25: X
A26: TC-DDIRULE-18 | B26: Lọc, phân trang và sắp xếp danh sách quy tắc | C26: Admin; 3 quy tắc chạm hoạt chất Alpha (một ở vị trí B), 1 quy tắc tên ngoài; thuốc phối hợp chứa hai hoạt chất | D26: 1. GET ?ingredient_id=Alpha 2. Thêm severity_level, interaction_type 3. limit=2, skip=2 4. q viết hoa khác tên 5. q theo tên ngoài 6. medication_id của thuốc phối hợp và của thuốc chưa có hoạt chất | E26: các bộ lọc như bước | F26: Chỉ các quy tắc mở khớp lọc; mới sửa trước; total không tính phân trang; q không phân biệt hoa thường; medication_id khớp bất kỳ hoạt chất của thuốc; thuốc chưa có hoạt chất → rỗng | G26: Đúng như mong đợi | H26: Pass | I26: AC8, AC26 · test_list_filters_paging_total_order__AC8_AC26 | Q26: 200, phiên bản mới, bản cũ superseded | U26: X
A27: TC-DDIRULE-19 | B27: Sửa nội dung giữ field khác; không đổi được cặp hoạt chất | C27: Admin; quy tắc phụ thuộc liều có 1 ngưỡng | D27: 1. PATCH expected_version=1, severity_level=3, description 2. PATCH gửi ingredient_a_id / ingredient_b_id / ingredient_b_external_name 3. PATCH đổi sang chong_chi_dinh mức 4 khi còn ngưỡng 4. PATCH như trên kèm dose_thresholds: [] | E27: như bước | F27: 200 với 2 field đổi, field khác giữ; đổi cặp 422 ValidationError; còn ngưỡng 422 threshold_not_allowed; kèm [] thì 200 và không còn ngưỡng | G27: Đúng như mong đợi | H27: Pass | I27: AC9 · test_patch_content_and_reject_pair_change__AC9
A28: TC-DDIRULE-20 | B28: Chặn người chưa đăng nhập và tài khoản không phải admin | C28: User thường; không token | D28: 1. Gọi lần lượt mọi endpoint /admin/drug-interactions..., /admin/drug-food-interactions, /admin/active-ingredients không token 2. Gọi lại bằng phiên của user thường 3. Đếm access_logs trước/sau | E28: 9 route | F28: 401 khi không token; 403 {"detail": "admin_only"} với user thường; access_logs không đổi; POST của user thường không ghi dòng nào | G28: Đúng như mong đợi | H28: Pass | I28: AC11 · Decision Table (R1, R2) · test_auth_401_and_non_admin_403__AC11, test_non_admin_write_changes_nothing__AC11
A29: TC-DDIRULE-21 | B29: Uống cách giờ: số giờ không bắt buộc, chỉ đi với cach_gio | C29: Admin; các hoạt chất mới | D29: 1. POST cach_gio + 2 giờ 2. POST cach_gio không số giờ 3. POST tranh_phoi_hop / can_theo_doi / giam_lieu kèm 2 giờ 4. PATCH đổi cach_gio → can_theo_doi khi còn số giờ 5. PATCH như trên kèm min_interval_hours: null | E29: như bước | F29: 201 với 2; 201 với null; 422 min_interval_not_allowed và không ghi; PATCH 422 min_interval_not_allowed; kèm null thì 200 | G29: Đúng như mong đợi | H29: Pass | I29: AC27 · EP (4, 5, 18) · test_min_interval_rules__AC27
A30: TC-DDIRULE-BVA-01 | B30: Biên severity_level | C30: Admin | D30: 1. POST với severity_level = 0, 1, 4 (chong_chi_dinh), 5 | E30: 0 / 1 / 4 / 5 | F30: 0 → 422; 1 → 201; 4 → 201; 5 → 422 | G30: Đúng như mong đợi | H30: Pass | I30: AC4 · BVA (min-1, min, max, max+1) · test_create_boundaries
A31: TC-DDIRULE-BVA-02 | B31: Biên min_interval_hours | C31: Admin; handling_type = cach_gio | D31: 1. POST với min_interval_hours = 0, 0.5, 168, 169 | E31: 0 / 0.5 / 168 / 169 | F31: 0 → 422; 0.5 → 201; 168 → 201; 169 → 422 | G31: Đúng như mong đợi | H31: Pass | I31: AC27 · BVA (min-1, min, max, max+1) · test_create_boundaries
A32: TC-DDIRULE-BVA-03 | B32: Biên độ dài description và source | C32: Admin | D32: 1. POST description dài 4000 và 4001 2. POST source dài 500 và 501 | E32: a*4000 / a*4001 / s*500 / s*501 | F32: 4000 → 201, 4001 → 422; 500 → 201, 501 → 422 | G32: Đúng như mong đợi | H32: Pass | I32: BVA (max, max+1) · test_create_boundaries
A33: TC-DDIRULE-BVA-04 | B33: Biên số ngưỡng liều | C33: Admin | D33: 1. POST với 20 ngưỡng 2. POST với 21 ngưỡng | E33: 20 / 21 ngưỡng | F33: 20 → 201 và trả đủ 20; 21 → 422 | G33: Đúng như mong đợi | H33: Pass | I33: BVA (max, max+1) · test_create_boundaries
A34: TC-DDIRULE-BVA-05 | B34: Biên limit của danh sách | C34: Admin | D34: 1. GET /admin/drug-interactions?limit=0, 1, 100, 101 | E34: 0 / 1 / 100 / 101 | F34: 0 → 422; 1 → 200; 100 → 200; 101 → 422 | G34: Đúng như mong đợi | H34: Pass | I34: AC8 · BVA (min-1, min, max, max+1) · test_list_limit_boundaries
A35: TC-DDIRULE-22 | B35: Sửa tạo phiên bản mới, phiên bản cũ giữ nguyên nội dung | C35: Admin; quy tắc R phiên bản 1 | D35: 1. PATCH expected_version=1, severity_level=3 2. So dòng DB phiên bản 1 trước và sau | E35: severity_level: 3 | F35: 200: cùng id, version = 2, version_id mới, updated_by = admin; DB có 2 dòng, phiên bản 1 nội dung không đổi và superseded_at có giá trị | G35: Đúng như mong đợi | H35: Pass | I35: AC18 · Decision Table bảng 2 (R4) · Chuyển trạng thái (current → superseded) · test_patch_creates_new_version_old_unchanged__AC18
A36: TC-DDIRULE-23 | B36: Ngưỡng liều thuộc từng phiên bản | C36: Admin; quy tắc có 2 ngưỡng | D36: 1. PATCH chỉ đổi description 2. PATCH gửi 1 ngưỡng mới 3. Đọc ngưỡng của từng phiên bản trong DB | E36: như bước | F36: Phiên bản 2 có 2 ngưỡng id mới; phiên bản 3 có 1 ngưỡng; ngưỡng của phiên bản 1 không đổi | G36: Đúng như mong đợi | H36: Pass | I36: AC19 · test_thresholds_belong_to_each_version__AC19
A37: TC-DDIRULE-24 | B37: Từ chối sửa/xóa với expected_version cũ | C37: Admin; quy tắc đã lên phiên bản 2 | D37: 1. PATCH expected_version=1 2. DELETE ?expected_version=1 | E37: expected_version: 1 | F37: 409 {"detail": "version_conflict"} cho cả hai; DB không đổi | G37: 409 version_conflict; vẫn 2 phiên bản, chưa xóa | H37: Pass | I37: AC20 · EP (26) · Decision Table bảng 2 (R2) · test_stale_expected_version_conflict__AC20
A38: TC-DDIRULE-25 | B38: Hai admin sửa cùng phiên bản đồng thời chỉ một thành công | C38: Admin; quy tắc phiên bản 1; một giao dịch khác giữ khóa quy tắc | D38: 1. Gửi đồng thời hai PATCH expected_version=1 với mô tả khác nhau 2. Chờ tới khi cả hai đang chờ khóa DB 3. Thả khóa 4. Đếm phiên bản | E38: 2 request song song | F38: Một 200, một 409; đúng 2 phiên bản, 1 phiên bản mở | G38: [200, 409]; phiên bản [1, 2] | H38: Pass | I38: AC20 · Chạy đua · test_concurrent_patch_same_version_one_wins__AC20
... A49: TC-DDIRULE-36 | B49: Response khớp contract (operationId, mã trạng thái, field) | C49: api_contract/openapi.json (đã duyệt) | D49: 1. So OpenAPI sinh từ app với contract cho 15 operation | E49: 15 operation | F49: operationId, mã trạng thái, shape request/response, tham số query khớp; bảng mức độ 1–4 có trong contract | G49: 28 test pass | H49: Pass | I49: AC14, AC17 · test_contract_interaction.py (unit)
G52: Pass | H52: =COUNTIF(H9:H49,"Pass")
...

Sheet Tương tác thuốc-thực phẩm
A1: Project Name | B1: DrugTime
A2: Module Name | B2: Danh mục tương tác thuốc-thực phẩm (admin) (DFIRULE)
A3: Created By | B3: zannguyen
A4: Creation Date | B4: 46307
A5: Reviewed By
A6: Reviewed Date
K7: Equivalence Partitioning
A8: Test Case ID | B8: Description | C8: Precondition | D8: Test Steps | E8: Test Data | F8: Expected Result | G8: Actual Result | H8: Status | I8: Comments(if any) | K8: Field | L8: Valid | M8: Num | N8: Invalid | O8: Num
A9: TC-DFIRULE-01 | B9: Tạo, xem, sửa, xóa mềm, xem lịch sử, tạo lại quy tắc thực phẩm | C9: Admin; hoạt chất có trong danh mục | D9: 1. POST /admin/drug-food-interactions 2. GET chi tiết 3. PATCH expected_version=1 đổi food_to_avoid, reason, severity_level 4. DELETE ?expected_version=2 5. GET chi tiết, GET lịch sử, GET phiên bản 1 6. POST lại cùng thực phẩm | E9: food_to_avoid: Nước bưởi chùm → Rượu | F9: 201 version 1; GET bằng response tạo; 200 version 2; DB có 2 phiên bản, bản 1 superseded; 204; 404; lịch sử deleted/superseded; phiên bản 1 giữ Nước bưởi chùm; tạo lại 201 | G9: Đúng như mong đợi | H9: Pass | I9: AC10, AC7, AC18 · Chuyển trạng thái · test_crud_flow__AC10 | K9: ingredient_id | L9: có trong danh mục | M9: 1 | N9: không tồn tại gửi khi sửa | O9: 3 4
A10: TC-DFIRULE-02 | B10: Từ chối dữ liệu sai và không ghi gì | C10: Admin | D10: 1. POST với hoạt chất không tồn tại 2. food_to_avoid chỉ khoảng trắng 3. severity_level = 5 4. có verification_status 5. thiếu source | E10: như bước | F10: 422 (hoạt chất không tồn tại: {"detail": "active_ingredient_not_found"}); không có dòng mới | G10: Đúng như mong đợi | H10: Pass | I10: AC10, AC4, AC15 · EP (3, 5) · test_validation_errors_write_nothing__AC10_AC4 | K10: food_to_avoid | L10: 1–200 ký tự, có ký tự không phải khoảng trắng | M10: 2 | N10: chỉ khoảng trắng trùng (không phân biệt hoa thường) với quy tắc mở của cùng hoạt chất | O10: 5 6
A11: TC-DFIRULE-03 | B11: Báo trùng thực phẩm không phân biệt hoa thường | C11: Admin; đã có (hoạt chất H, "Bưởi") | D11: 1. POST (H, "BƯỞI") 2. POST (hoạt chất khác, "Bưởi") | E11: BƯỞI | F11: 409 interaction_rule_exists; hoạt chất khác thì 201 | G11: Đúng như mong đợi | H11: Pass | I11: AC10, AC5 · EP (6) · test_duplicate_food_case_insensitive__AC10_AC5
